反爬虫问题
目前判断问题在于，被识别出来了
```
🚀 Starting API endpoint scan...
🎯 Starting scan target: https://www.ray.so/
✗ Failed to get HTML https://www.ray.so/_next/static/chunks/1684-2225e4b9de719f30.js: 
('Connection aborted.', ConnectionResetError(10054, 
'远程主机强迫关闭了一个现有的连接。', None, 10054, None))
⚠ Cannot get external script:
https://www.ray.so/_next/static/chunks/1684-2225e4b9de719f30.js
✗ Failed to get HTML https://www.ray.so/_next/static/chunks/7239-fb38f3cb99a9814e.js: 
('Connection aborted.', ConnectionResetError(10054,
'远程主机强迫关闭了一个现有的连接。', None, 10054, None))
⚠ Cannot get external script:
https://www.ray.so/_next/static/chunks/7239-fb38f3cb99a9814e.js
✗ Failed to get HTML https://www.ray.so/_next/static/chunks/7328-5202ec326627545d.js: 
('Connection aborted.', ConnectionResetError(10054,
'远程主机强迫关闭了一个现有的连接。', None, 10054, None))
⚠ Cannot get external script:
https://www.ray.so/_next/static/chunks/7328-5202ec326627545d.js
✗ Failed to get HTML https://www.ray.so/_next/static/chunks/9613-8cbc04e102e303bb.js: 
('Connection aborted.', ConnectionResetError(10054,
'远程主机强迫关闭了一个现有的连接。', None, 10054, None))
```
目前改进方案是加上了更加完全真实的请求头
配合上我们的自己的ua_manager.py
```python
 header = {`
        `"User-Agent": Uam.getUa(),`
        `"Accept": "text/html,application/xhtml+xml,application/xml;q=0.9,image/webp,*/*;q=0.8",`
        `"Accept-Language": "zh-CN,zh;q=0.9,en;q=0.8",`
        `"Accept-Encoding": "gzip, deflate, br",`
        `"Connection": "keep-alive",`
        `"Upgrade-Insecure-Requests": "1",`
        `"Sec-Fetch-Dest": "document",`
        `"Sec-Fetch-Mode": "navigate",`
        `"Sec-Fetch-Site": "none",`
        `"Cache-Control": "max-age=0"`
    `}
```